a = 'Traceback (most recent call last):\n  File "/var/task/lambda_function.py", line 61, in make_prediction\n    s3.download_file(bucket_name, \'model.onnx\', model_path)\n  File "/var/lang/lib/python3.12/site-packages/boto3/s3/inject.py", line 192, in download_file\n    return transfer.download_file(\n           ^^^^^^^^^^^^^^^^^^^^^^^\n  File "/var/lang/lib/python3.12/site-packages/boto3/s3/transfer.py", line 406, in download_file\n    future.result()\n  File "/var/lang/lib/python3.12/site-packages/s3transfer/futures.py", line 103, in result\n    return self._coordinator.result()\n           ^^^^^^^^^^^^^^^^^^^^^^^^^^\n  File "/var/lang/lib/python3.12/site-packages/s3transfer/futures.py", line 266, in result\n    raise self._exception\n  File "/var/lang/lib/python3.12/site-packages/s3transfer/tasks.py", line 269, in _main\n    self._submit(transfer_future=transfer_future, **kwargs)\n  File "/var/lang/lib/python3.12/site-packages/s3transfer/download.py", line 354, in _submit\n    response = client.head_object(\n               ^^^^^^^^^^^^^^^^^^^\n  File "/var/lang/lib/python3.12/site-packages/botocore/client.py", line 569, in _api_call\n    return self._make_api_call(operation_name, kwargs)\n           ^^^^^^^^^^^^^^^^^^^^^^^^^^^^^^^^^^^^^^^^^^^\n  File "/var/lang/lib/python3.12/site-packages/botocore/client.py", line 1023, in _make_api_call\n    raise error_class(parsed_response, operation_name)\nbotocore.exceptions.ClientError: An error occurred (404) when calling the HeadObject operation: Not Found\n'

print(a)